Workbook

Sheet MBD_structure_classification
A1: MeCP2 MBD mutation structural classification (3C2I-based)
A2: MBD is defined as residues 78–162. Structural classification is assigned only where 3C2I contains resolved atomic coordinates; unresolved MBD positions are retained and marked as structurally unresolved.
A4: Unique_protein_change | B4: Protein_position | C4: Protein_level_group | D4: Preferred_classification | E4: Structure_status | F4: Structural_category | G4: Structure_residue_label | H4: SASA_isolated_A2 | I4: SASA_protein_A2 | J4: SASA_complex_A2 | K4: Exposure_ratio | L4: Delta_SASA_DNA_A2 | M4: DNA_buried_ratio | N4: SNV_count | O4: Variation_IDs | P4: NM_004992.4_c_HGVS | Q4: NP_004983.1_p_HGVS | R4: RTT_evidence_level | S4: Classification_source | T4: Classification_scope | U4: Original_RTT_RCV_classifications | V4: VCV_global_classifications | W4: Protein_level_detailed_classification | X4: Use_VCV_global_fallback | Y4: Include_in_strict_RTT_PLP | Z4: Include_in_hierarchical_PLP | AA4: Classification_basis | AB4: RCV_accessions | AC4: RCV_conditions | AD4: RCV_review_status | AE4: RCV_date_last_evaluated | AF4: RCV_submission_count | AG4: ClinVar_URLs
A5: K82R | B5: 82 | C5: B/LB group | D5: Likely benign | E5: Structurally unresolved in 3C2I | F5: NA | N5: 1 | O5: 143509 | P5: NM_004992.4:c.245A>G | Q5: NP_004983.1:p.Lys82Arg | R5: Exact Rett syndrome RCV | S5: Exact Rett syndrome RCV | T5: RTT-specific | U5: Likely benign | V5: Benign/Likely benign | W5: Likely benign | X5: No | Y5: No | Z5: No | AA5: Exact RTT RCV classification: Likely benign | AB5: RCV003380473.1 | AC5: Rett syndrome | AD5: criteria provided, single submitter | AE5: 2023-08-14 | AF5: 1 | AG5: https://www.ncbi.nlm.nih.gov/clinvar/variation/143509/
A6: R85C | B6: 85 | C6: VUS | D6: Uncertain significance | E6: Structurally unresolved in 3C2I | F6: NA | N6: 1 | O6: 424578 | P6: NM_004992.4:c.253C>T | Q6: NP_004983.1:p.Arg85Cys | R6: Exact Rett syndrome RCV | S6: Exact Rett syndrome RCV | T6: RTT-specific | U6: Uncertain significance | V6: Uncertain significance | W6: Uncertain significance | X6: No | Y6: No | Z6: No | AA6: Exact RTT RCV classification: Uncertain significance | AB6: RCV001775123.6 | AC6: Rett syndrome | AD6: reviewed by expert panel | AE6: 2022-12-08 | AF6: 3 | AG6: https://www.ncbi.nlm.nih.gov/clinvar/variation/424578/
A7: S86C | B7: 86 | C7: VUS | D7: Uncertain significance | E7: Structurally unresolved in 3C2I | F7: NA | N7: 1 | O7: 143510 | P7: NM_004992.4:c.257C>G | Q7: NP_004983.1:p.Ser86Cys | R7: Exact Rett syndrome RCV | S7: Exact Rett syndrome RCV | T7: RTT-specific | U7: Uncertain significance | V7: Uncertain significance | W7: Uncertain significance | X7: No | Y7: No | Z7: No | AA7: Exact RTT RCV classification: Uncertain significance | AB7: RCV000133041.4 | AC7: Rett syndrome | AD7: criteria provided, single submitter | AE7: 2023-10-12 | AF7: 2 | AG7: https://www.ncbi.nlm.nih.gov/clinvar/variation/143510/
A8: R89C | B8: 89 | C8: B/LB group | D8: Benign | E8: Structurally unresolved in 3C2I | F8: NA | N8: 1 | O8: 590069 | P8: NM_004992.4:c.265C>T | Q8: NP_004983.1:p.Arg89Cys | R8: Exact Rett syndrome RCV | S8: Exact Rett syndrome RCV | T8: RTT-specific | U8: Benign | V8: Benign | W8: Benign | X8: No | Y8: No | Z8: No | AA8: Exact RTT RCV classification: Benign | AB8: RCV004584220.2 | AC8: Rett syndrome | AD8: reviewed by expert panel | AE8: 2024-04-18 | AF8: 1 | AG8: https://www.ncbi.nlm.nih.gov/clinvar/variation/590069/
A9: R91P | B9: 91 | C9: Not classified | D9: not provided | E9: Resolved in 3C2I | F9: Protein surface | G9: R91 | H9: 342.44876 | I9: 278.8877 | J9: 278.8877 | K9: 0.814392 | L9: 0 | M9: 0 | N9: 1 | O9: 2811757 | P9: NM_004992.4:c.272G>C | Q9: NP_004983.1:p.Arg91Pro | R9: Exact Rett syndrome RCV | S9: Exact Rett syndrome RCV | T9: RTT-specific | U9: not provided | V9: Uncertain significance | W9: not provided | X9: No | Y9: No | Z9: No | AA9: Exact RTT RCV exists, but no definitive germline classification is provided. | AB9: RCV003988136.3 | AC9: Rett syndrome | AD9: no classification provided | AE9: 24 | AF9: 1 | AG9: https://www.ncbi.nlm.nih.gov/clinvar/variation/2811757/
A10: R91Q | B10: 91 | C10: VUS | D10: Uncertain significance | E10: Resolved in 3C2I | F10: Protein surface | G10: R91 | H10: 342.44876 | I10: 278.8877 | J10: 278.8877 | K10: 0.814392 | L10: 0 | M10: 0 | N10: 1 | O10: 1000879 | P10: NM_004992.4:c.272G>A | Q10: NP_004983.1:p.Arg91Gln | R10: Exact Rett syndrome RCV | S10: Exact Rett syndrome RCV | T10: RTT-specific | U10: Uncertain significance | V10: Uncertain significance | W10: Uncertain significance | X10: No | Y10: No | Z10: No | AA10: Exact RTT RCV classification: Uncertain significance | AB10: RCV003485703.1 | AC10: Rett syndrome | AD10: criteria provided, single submitter | AE10: 2023-11-22 | AF10: 1 | AG10: https://www.ncbi.nlm.nih.gov/clinvar/variation/1000879/
A11: P93S | B11: 93 | C11: VUS | D11: Uncertain significance | E11: Resolved in 3C2I | F11: Protein surface | G11: P93 | H11: 237.04889 | I11: 50.151764 | J11: 50.151764 | K11: 0.211567 | L11: 0 | M11: 0 | N11: 1 | O11: 143515 | P11: NM_004992.4:c.277C>T | Q11: NP_004983.1:p.Pro93Ser | R11: Exact Rett syndrome RCV | S11: Exact Rett syndrome RCV | T11: RTT-specific | U11: Uncertain significance | V11: Conflicting classifications of pathogenicity | W11: Uncertain significance | X11: No | Y11: No | Z11: No | AA11: Exact RTT RCV classification: Uncertain significance | AB11: RCV000133046.4 | AC11: Rett syndrome | AD11: criteria provided, single submitter | AE11: 2024-03-18 | AF11: 2 | AG11: https://www.ncbi.nlm.nih.gov/clinvar/variation/143515/
A12: D97E | B12: 97 | C12: VUS | D12: Uncertain significance | E12: Resolved in 3C2I | F12: Protein interior | G12: D97 | H12: 246.02556 | I12: 19.081558 | J12: 19.081558 | K12: 0.077559 | L12: 0 | M12: 0 | N12: 1 | O12: 143520 | P12: NM_004992.4:c.291C>A | Q12: NP_004983.1:p.Asp97Glu | R12: Exact Rett syndrome RCV | S12: Exact Rett syndrome RCV | T12: RTT-specific | U12: Uncertain significance | V12: Uncertain significance | W12: Uncertain significance | X12: No | Y12: No | Z12: No | AA12: Exact RTT RCV classification: Uncertain significance | AB12: RCV000133051.4 | AC12: Rett syndrome | AD12: criteria provided, single submitter | AE12: 2023-10-12 | AF12: 2 | AG12: https://www.ncbi.nlm.nih.gov/clinvar/variation/143520/
A13: D97Y | B13: 97 | C13: P/LP group | D13: Likely pathogenic | E13: Resolved in 3C2I | F13: Protein interior | G13: D97 | H13: 246.02556 | I13: 19.081558 | J13: 19.081558 | K13: 0.077559 | L13: 0 | M13: 0 | N13: 1 | O13: 143517 | P13: NM_004992.4:c.289G>T | Q13: NP_004983.1:p.Asp97Tyr | R13: Exact Rett syndrome RCV | S13: Exact Rett syndrome RCV | T13: RTT-specific | U13: Likely pathogenic | V13: Likely pathogenic | W13: Likely pathogenic | X13: No | Y13: Yes | Z13: Yes | AA13: Exact RTT RCV classification: Likely pathogenic | AB13: RCV000133048.5 | AC13: Rett syndrome | AD13: criteria provided, single submitter | AE13: 2024-01-10 | AF13: 2 | AG13: https://www.ncbi.nlm.nih.gov/clinvar/variation/143517/
A14: T99P | B14: 99 | C14: VUS | D14: Uncertain significance | E14: Resolved in 3C2I | F14: Protein surface | G14: T99 | H14: 247.11879 | I14: 116.36423 | J14: 116.36423 | K14: 0.470884 | L14: 0 | M14: 0 | N14: 1 | O14: 859603 | P14: NM_004992.4:c.295A>C | Q14: NP_004983.1:p.Thr99Pro | R14: Exact Rett syndrome RCV | S14: Exact Rett syndrome RCV | T14: RTT-specific | U14: Uncertain significance | V14: Uncertain significance | W14: Uncertain significance | X14: No | Y14: No | Z14: No | AA14: Exact RTT RCV classification: Uncertain significance | AB14: RCV001507069.5 | AC14: Rett syndrome | AD14: reviewed by expert panel | AE14: 2026-01-28 | AF14: 1 | AG14: https://www.ncbi.nlm.nih.gov/clinvar/variation/859603/
A15: L100R | B15: 100 | C15: VUS | D15: Uncertain significance | E15: Resolved in 3C2I | F15: Protein interior | G15: L100 | H15: 279.48074 | I15: 17.349607 | J15: 17.349607 | K15: 0.062078 | L15: 0 | M15: 0 | N15: 1 | O15: 143523 | P15: NM_004992.4:c.299T>G | Q15: NP_004983.1:p.Leu100Arg | R15: Exact Rett syndrome RCV | S15: Exact Rett syndrome RCV | T15: RTT-specific | U15: Uncertain significance | V15: Uncertain significance | W15: Uncertain significance | X15: No | Y15: No | Z15: No | AA15: Exact RTT RCV classification: Uncertain significance | AB15: RCV000133055.5 | AC15: Rett syndrome | AD15: criteria provided, single submitter | AE15: 2024-01-11 | AF15: 2 | AG15: https://www.ncbi.nlm.nih.gov/clinvar/variation/143523/
A16: L100V | B16: 100 | C16: P/LP group | D16: Pathogenic | E16: Resolved in 3C2I | F16: Protein interior | G16: L100 | H16: 279.48074 | I16: 17.349607 | J16: 17.349607 | K16: 0.062078 | L16: 0 | M16: 0 | N16: 1 | O16: 11835 | P16: NM_004992.4:c.298C>G | Q16: NP_004983.1:p.Leu100Val | R16: Exact Rett syndrome RCV | S16: Exact Rett syndrome RCV | T16: RTT-specific | U16: Pathogenic | V16: Pathogenic | W16: Pathogenic | X16: No | Y16: Yes | Z16: Yes | AA16: Exact RTT RCV classification: Pathogenic | AB16: RCV000012608.30 | AC16: Rett syndrome | AD16: reviewed by expert panel | AE16: 2022-05-10 | AF16: 4 | AG16: https://www.ncbi.nlm.nih.gov/clinvar/variation/11835/
A17: P101H | B17: 101 | C17: P/LP group | D17: Likely pathogenic | E17: Resolved in 3C2I | F17: Protein interior | G17: P101 | H17: 237.40399 | I17: 29.127611 | J17: 29.127611 | K17: 0.122692 | L17: 0 | M17: 0 | N17: 1 | O17: 143525 | P17: NM_004992.4:c.302C>A | Q17: NP_004983.1:p.Pro101His | R17: Exact Rett syndrome RCV | S17: Exact Rett syndrome RCV | T17: RTT-specific | U17: Likely pathogenic | V17: Likely pathogenic | W17: Likely pathogenic | X17: No | Y17: Yes | Z17: Yes | AA17: Exact RTT RCV classification: Likely pathogenic | AB17: RCV000133057.4 | AC17: Rett syndrome | AD17: criteria provided, single submitter | AE17: 2023-10-12 | AF17: 2 | AG17: https://www.ncbi.nlm.nih.gov/clinvar/variation/143525/
A18: P101L | B18: 101 | C18: P/LP group | D18: Likely pathogenic | E18: Resolved in 3C2I | F18: Protein interior | G18: P101 | H18: 237.40399 | I18: 29.127611 | J18: 29.127611 | K18: 0.122692 | L18: 0 | M18: 0 | N18: 1 | O18: 143527 | P18: NM_004992.4:c.302C>T | Q18: NP_004983.1:p.Pro101Leu | R18: Exact Rett syndrome RCV | S18: Exact Rett syndrome RCV | T18: RTT-specific | U18: Likely pathogenic | V18: Likely pathogenic | W18: Likely pathogenic | X18: No | Y18: Yes | Z18: Yes | AA18: Exact RTT RCV classification: Likely pathogenic | AB18: RCV000133059.4 | AC18: Rett syndrome | AD18: criteria provided, single submitter | AE18: 2024-03-20 | AF18: 2 | AG18: https://www.ncbi.nlm.nih.gov/clinvar/variation/143527/
A19: P101R | B19: 101 | C19: P/LP group | D19: Pathogenic | E19: Resolved in 3C2I | F19: Protein interior | G19: P101 | H19: 237.40399 | I19: 29.127611 | J19: 29.127611 | K19: 0.122692 | L19: 0 | M19: 0 | N19: 1 | O19: 143526 | P19: NM_004992.4:c.302C>G | Q19: NP_004983.1:p.Pro101Arg | R19: Exact Rett syndrome RCV | S19: Exact Rett syndrome RCV | T19: RTT-specific | U19: Pathogenic | V19: Pathogenic | W19: Pathogenic | X19: No | Y19: Yes | Z19: Yes | AA19: Exact RTT RCV classification: Pathogenic | AB19: RCV000170238.12 | AC19: Rett syndrome | AD19: reviewed by expert panel | AE19: 2022-04-28 | AF19: 5 | AG19: https://www.ncbi.nlm.nih.gov/clinvar/variation/143526/
A20: P101S | B20: 101 | C20: P/LP group | D20: Pathogenic | E20: Resolved in 3C2I | F20: Protein interior | G20: P101 | H20: 237.40399 | I20: 29.127611 | J20: 29.127611 | K20: 0.122692 | L20: 0 | M20: 0 | N20: 1 | O20: 143524 | P20: NM_004992.4:c.301C>T | Q20: NP_004983.1:p.Pro101Ser | R20: Exact Rett syndrome RCV | S20: Exact Rett syndrome RCV | T20: RTT-specific | U20: Pathogenic | V20: Pathogenic | W20: Pathogenic | X20: No | Y20: Yes | Z20: Yes | AA20: Exact RTT RCV classification: Pathogenic | AB20: RCV000133056.12 | AC20: Rett syndrome | AD20: reviewed by expert panel | AE20: 2021-03-26 | AF20: 4 | AG20: https://www.ncbi.nlm.nih.gov/clinvar/variation/143524/
... A92: R162G | B92: 162 | C92: P/LP group | D92: Pathogenic | E92: Resolved in 3C2I | F92: Protein surface | G92: R162 | H92: 341.41058 | I92: 185.79651 | J92: 185.46167 | K92: 0.544203 | L92: 0.334839 | M92: 0.001802 | N92: 1 | O92: 180209 | P92: NM_004992.4:c.484A>G | Q92: NP_004983.1:p.Arg162Gly | R92: Exact Rett syndrome RCV | S92: Exact Rett syndrome RCV | T92: RTT-specific | U92: Pathogenic | V92: Pathogenic | W92: Pathogenic | X92: No | Y92: Yes | Z92: Yes | AA92: Exact RTT RCV classification: Pathogenic | AB92: RCV000157062.3 | AC92: Rett syndrome | AD92: no assertion criteria provided | AE92: 2014-12-10 | AF92: 1 | AG92: https://www.ncbi.nlm.nih.gov/clinvar/variation/180209/

Sheet Structure_summary
A1: MeCP2 MBD structural-classification summary
A3: Metric | B3: Value
A4: All MBD protein substitutions | B4: =COUNTA(MBD_structure_classification!A5:A92) -> 88
A5: Resolved in 3C2I | B5: =COUNTIF(MBD_structure_classification!E5:E92,"Resolved in 3C2I") -> 84
A6: Structurally unresolved in 3C2I | B6: =COUNTIF(MBD_structure_classification!E5:E92,"Structurally unresolved in 3C2I") -> 4
A7: Structural coverage | B7: =B5/B4 -> 0.95454545
A9: Structural category | B9: Variant count | C9: % of resolved variants | D9: % of all MBD variants
A10: Protein interior | B10: =COUNTIF(MBD_structure_classification!F5:F92,"Protein interior") -> 40 | C10: =B10/$B$5 -> 0.47619048 | D10: =B10/$B$4 -> 0.45454545
A11: Protein surface | B11: =COUNTIF(MBD_structure_classification!F5:F92,"Protein surface") -> 17 | C11: =B11/$B$5 -> 0.20238095 | D11: =B11/$B$4 -> 0.19318182
A12: Protein-DNA interface | B12: =COUNTIF(MBD_structure_classification!F5:F92,"Protein-DNA interface") -> 27 | C12: =B12/$B$5 -> 0.32142857 | D12: =B12/$B$4 -> 0.30681818
A13: Total resolved | B13: =SUM(B10:B12) -> 84 | C13: =SUM(C10:C12) -> 1 | D13: =SUM(D10:D12) -> 0.95454545
A16: Protein-level clinical group | B16: Protein interior | C16: Protein surface | D16: Protein-DNA interface | E16: Structurally unresolved | F16: Total | G16: % of group resolved | H16: Notes
A17: P/LP group | B17: =COUNTIFS(MBD_structure_classification!C5:C92,$A17,MBD_structure_classification!F5:F92,"Protein interior") -> 33 | C17: =COUNTIFS(MBD_structure_classification!C5:C92,$A17,MBD_structure_classification!F5:F92,"Protein surface") -> 8 | D17: =COUNTIFS(MBD_structure_classification!C5:C92,$A17,MBD_structure_classification!F5:F92,"Protein-DNA interface") -> 22 | E17: =COUNTIFS(MBD_structure_classification!C5:C92,$A17,MBD_structure_classification!F5:F92,"NA") -> 0 | F17: =SUM(B17:E17) -> 63 | G17: =IF(F17=0,0,SUM(B17:D17)/F17) -> 1 | H17: All MBD substitutions are retained regardless of clinical classification.
A18: VUS | B18: =COUNTIFS(MBD_structure_classification!C5:C92,$A18,MBD_structure_classification!F5:F92,"Protein interior") -> 7 | C18: =COUNTIFS(MBD_structure_classification!C5:C92,$A18,MBD_structure_classification!F5:F92,"Protein surface") -> 7 | D18: =COUNTIFS(MBD_structure_classification!C5:C92,$A18,MBD_structure_classification!F5:F92,"Protein-DNA interface") -> 3 | E18: =COUNTIFS(MBD_structure_classification!C5:C92,$A18,MBD_structure_classification!F5:F92,"NA") -> 2 | F18: =SUM(B18:E18) -> 19 | G18: =IF(F18=0,0,SUM(B18:D18)/F18) -> 0.89473684
A19: B/LB group | B19: =COUNTIFS(MBD_structure_classification!C5:C92,$A19,MBD_structure_classification!F5:F92,"Protein interior") -> 0 | C19: =COUNTIFS(MBD_structure_classification!C5:C92,$A19,MBD_structure_classification!F5:F92,"Protein surface") -> 1 | D19: =COUNTIFS(MBD_structure_classification!C5:C92,$A19,MBD_structure_classification!F5:F92,"Protein-DNA interface") -> 1 | E19: =COUNTIFS(MBD_structure_classification!C5:C92,$A19,MBD_structure_classification!F5:F92,"NA") -> 2 | F19: =SUM(B19:E19) -> 4 | G19: =IF(F19=0,0,SUM(B19:D19)/F19) -> 0.5
A20: ClinVar conflicting | B20: =COUNTIFS(MBD_structure_classification!C5:C92,$A20,MBD_structure_classification!F5:F92,"Protein interior") -> 0 | C20: =COUNTIFS(MBD_structure_classification!C5:C92,$A20,MBD_structure_classification!F5:F92,"Protein surface") -> 0 | D20: =COUNTIFS(MBD_structure_classification!C5:C92,$A20,MBD_structure_classification!F5:F92,"Protein-DNA interface") -> 1 | E20: =COUNTIFS(MBD_structure_classification!C5:C92,$A20,MBD_structure_classification!F5:F92,"NA") -> 0 | F20: =SUM(B20:E20) -> 1 | G20: =IF(F20=0,0,SUM(B20:D20)/F20) -> 1
A21: Mixed classification | B21: =COUNTIFS(MBD_structure_classification!C5:C92,$A21,MBD_structure_classification!F5:F92,"Protein interior") -> 0 | C21: =COUNTIFS(MBD_structure_classification!C5:C92,$A21,MBD_structure_classification!F5:F92,"Protein surface") -> 0 | D21: =COUNTIFS(MBD_structure_classification!C5:C92,$A21,MBD_structure_classification!F5:F92,"Protein-DNA interface") -> 0 | E21: =COUNTIFS(MBD_structure_classification!C5:C92,$A21,MBD_structure_classification!F5:F92,"NA") -> 0 | F21: =SUM(B21:E21) -> 0 | G21: =IF(F21=0,0,SUM(B21:D21)/F21) -> 0
A22: Not classified | B22: =COUNTIFS(MBD_structure_classification!C5:C92,$A22,MBD_structure_classification!F5:F92,"Protein interior") -> 0 | C22: =COUNTIFS(MBD_structure_classification!C5:C92,$A22,MBD_structure_classification!F5:F92,"Protein surface") -> 1 | D22: =COUNTIFS(MBD_structure_classification!C5:C92,$A22,MBD_structure_classification!F5:F92,"Protein-DNA interface") -> 0 | E22: =COUNTIFS(MBD_structure_classification!C5:C92,$A22,MBD_structure_classification!F5:F92,"NA") -> 0 | F22: =SUM(B22:E22) -> 1 | G22: =IF(F22=0,0,SUM(B22:D22)/F22) -> 1
A25: Unresolved mutation | B25: Position | C25: Protein-level group | D25: Preferred classification
A26: K82R | B26: 82 | C26: B/LB group | D26: Likely benign
A27: R85C | B27: 85 | C27: VUS | D27: Uncertain significance
A28: S86C | B28: 86 | C28: VUS | D28: Uncertain significance
A29: R89C | B29: 89 | C29: B/LB group | D29: Benign

Sheet Class_lists
A1: MBD mutations grouped by 3C2I structural category
A3: Protein interior | B3: Protein surface | C3: Protein-DNA interface | D3: Structurally unresolved | F3: Category | G3: Count
A4: D97E | B4: R91P | C4: R111G | D4: K82R | F4: Protein interior | G4: 40
A5: D97Y | B5: R91Q | C5: R111K | D5: R85C | F5: Protein surface | G5: 17
A6: L100R | B6: P93S | C6: G114A | D6: S86C | F6: Protein-DNA interface | G6: 27
A7: L100V | B7: T99P | C7: R115C | D7: R89C | F7: Structurally unresolved | G7: 4
A8: P101H | B8: A117G | C8: R115H
A9: P101L | B9: P127L | C9: Y120D
A10: P101R | B10: Q128P | C10: D121G
A11: P101S | B11: K135E | C11: D121N
A12: G103D | B12: E143K | C12: D121V
A13: W104R | B13: K144R | C13: G129V
A14: R106G | B14: D147N | C14: K130R
A15: R106L | B15: T148A | C15: A131D
A16: R106Q | B16: S149Y | C16: R133C
A17: R106W | B17: D151A | C17: R133G
A18: L108H | B18: D151G | C18: R133H
A19: L108P | B19: D151Y | C19: R133L
A20: G118E | B20: R162G | C20: R133P
A21: V122A | C21: S134C
A22: V122M | C22: S134F
A23: L124F | C23: S134P
A24: L124W | C24: A140V
A25: N126I | C25: F157I
A26: N126S | C26: F157L
A27: L138F | C27: T158A
A28: L138S | C28: T158M
A29: Y141C | C29: T158R
A30: P152A | C30: T160S
A31: P152L
A32: P152R
A33: P152T
A34: F155C
A35: F155I
A36: F155S
A37: D156A
A38: D156E
A39: D156G
A40: D156Y
A41: G161E
...

Sheet Classification_rules
A1: Structural classification rules
A3: Item | B3: Definition / rule
A4: Biological MBD range | B4: MeCP2-e2 residues 78–162
A5: 3C2I structurally resolved range used here | B5: Residues 91–162
A6: DNA buried ratio | B6: (SASA_protein - SASA_complex) / SASA_protein
A7: Protein-DNA interface | B7: DNA_buried_ratio > 0.01
A8: Exposure ratio | B8: SASA_protein / SASA_isolated
A9: Protein interior | B9: Non-interface residue with Exposure_ratio < 0.20
A10: Protein surface | B10: Non-interface residue with Exposure_ratio >= 0.20
A11: Classification priority | B11: Protein-DNA interface > Protein interior > Protein surface
A13: Residues in the biological MBD that lack resolved atomic coordinates in 3C2I are retained in the MBD mutation dataset but are marked as structurally unresolved and excluded from the interior/surface/DNA-interface comparison.

Sheet SASA_residue_reference
A1: 3C2I residue-level SASA reference used for mutation mapping
A3: Chain | B3: PDB_residue_number | C3: Residue_name | D3: Residue_label | E3: SASA_isolated_A2 | F3: SASA_protein_A2 | G3: SASA_complex_A2 | H3: Exposure_ratio | I3: Delta_SASA_DNA_A2 | J3: DNA_buried_ratio | K3: Structural_category
A4: A | B4: 91 | C4: ARG | D4: R91 | E4: 342.44876 | F4: 278.8877 | G4: 278.8877 | H4: 0.814392 | I4: 0 | J4: 0 | K4: Protein surface
A5: A | B5: 92 | C5: GLY | D5: G92 | E5: 186.84369 | F5: 40.448566 | G5: 40.448566 | H5: 0.216483 | I5: 0 | J5: 0 | K5: Protein surface
A6: A | B6: 93 | C6: PRO | D6: P93 | E6: 237.04889 | F6: 50.151764 | G6: 50.151764 | H6: 0.211567 | I6: 0 | J6: 0 | K6: Protein surface
A7: A | B7: 94 | C7: MET | D7: M94 | E7: 307.29025 | F7: 60.133881 | G7: 60.133881 | H7: 0.195691 | I7: 0 | J7: 0 | K7: Protein interior
A8: A | B8: 95 | C8: TYR | D8: Y95 | E8: 332.18988 | F8: 101.28543 | G8: 101.28543 | H8: 0.304902 | I8: 0 | J8: 0 | K8: Protein surface
A9: A | B9: 96 | C9: ASP | D9: D96 | E9: 265.48206 | F9: 100.68463 | G9: 100.68463 | H9: 0.379252 | I9: 0 | J9: 0 | K9: Protein surface
A10: A | B10: 97 | C10: ASP | D10: D97 | E10: 246.02556 | F10: 19.081558 | G10: 19.081558 | H10: 0.077559 | I10: 0 | J10: 0 | K10: Protein interior
A11: A | B11: 98 | C11: PRO | D11: P98 | E11: 233.83502 | F11: 101.21938 | G11: 101.21938 | H11: 0.432867 | I11: 0 | J11: 0 | K11: Protein surface
A12: A | B12: 99 | C12: THR | D12: T99 | E12: 247.11879 | F12: 116.36423 | G12: 116.36423 | H12: 0.470884 | I12: 0 | J12: 0 | K12: Protein surface
A13: A | B13: 100 | C13: LEU | D13: L100 | E13: 279.48074 | F13: 17.349607 | G13: 17.349607 | H13: 0.062078 | I13: 0 | J13: 0 | K13: Protein interior
A14: A | B14: 101 | C14: PRO | D14: P101 | E14: 237.40399 | F14: 29.127611 | G14: 29.127611 | H14: 0.122692 | I14: 0 | J14: 0 | K14: Protein interior
A15: A | B15: 102 | C15: GLU | D15: E102 | E15: 279.77991 | F15: 173.21582 | G15: 173.21582 | H15: 0.619115 | I15: 0 | J15: 0 | K15: Protein surface
... A75: A | B75: 162 | C75: ARG | D75: R162 | E75: 341.41058 | F75: 185.79651 | G75: 185.46167 | H75: 0.544203 | I75: 0.334839 | J75: 0.001802 | K75: Protein surface
